Workbook

Sheet 12_24
C1: Gesamt | D1: Inb. | E1: % | F1: Out. | G1: % | H1: >36 | I1: % | J1: <36 | K1: % | L1: 3 - 36 | M1: % | N1: < 3 | O1: % | P1: < 1 | Q1: % | R1: Inb spät | T1: % | U1: Out spät | V1: % | X1: WCH-R | Y1: WCH-S | Z1: WCH-C | AA1: Maas | AB1: Blind | AC1: Taub | AD1: Stre
C2: =M4 | D2: =H4 | E2: =#N/A | F2: =H5 | G2: =#N/A | H2: =M5 | I2: =#N/A | J2: =L5 | K2: =#N/A | L2: =K5 | M2: =#N/A | N2: =J5 | O2: =#N/A | P2: =I5 | Q2: =#N/A | X2: =X5 | Y2: =Y5 | Z2: =Z5 | AA2: =AA5 | AB2: =AB5 | AC2: =AC5 | AD2: =AD5 | AE2: =M5
A4: INb | H4: =SUMPRODUCT(SUBTOTAL(3,INDIRECT("I"&ROW(H7:H10130)))*(H7:H10130="Inbound")) | M4: =L5+M5 | X4: =X5+Y5+Z5+AA5+AB5+AC5+AD5
A5: Out | H5: =SUMPRODUCT(SUBTOTAL(3,INDIRECT("I"&ROW(H7:H10130)))*(H7:H10130="Outbound")) | I5: =SUBTOTAL(9,I7:I10130) | J5: =SUBTOTAL(9,J7:J10130) | K5: =SUBTOTAL(9,K7:K10130) | L5: =SUBTOTAL(9,L7:L10130) | M5: =SUBTOTAL(9,M7:M10130) | X5: =SUMPRODUCT(SUBTOTAL(3,INDIRECT("W"&ROW(7:10130)))*($W$7:$W$10130="R")) | Y5: =SUMPRODUCT(SUBTOTAL(3,INDIRECT("W"&ROW(7:10130)))*($W$7:$W$10130="S")) | Z5: =SUMPRODUCT(SUBTOTAL(3,INDIRECT("W"&ROW(7:10130)))*($W$7:$W$10130="C")) | AA5: =SUMPRODUCT(SUBTOTAL(3,INDIRECT("W"&ROW(7:10130)))*($W$7:$W$10130="M")) | AB5: =SUMPRODUCT(SUBTOTAL(3,INDIRECT("W"&ROW(7:10130)))*($W$7:$W$10130="B")) | AC5: =SUMPRODUCT(SUBTOTAL(3,INDIRECT("W"&ROW(7:10130)))*($W$7:$W$10130="T")) | AD5: =SUMPRODUCT(SUBTOTAL(3,INDIRECT("W"&ROW(7:10130)))*($W$7:$W$10130="ST"))
A6: Airline | B6: FlugNr. | C6: E-Datum | D6: Zeit | E6: M. am | F6: M. um | G6: Stunden | H6: InOut | I6: < 1 h | J6: 1-3 h | K6: 3 - 36 h | L6: <36 | M6: >36 h | N6: Sita | O6: E-Mail | P6: PSM | Q6: Staff | R6: Tel. | T6: von Airport | U6: von Airport | V6: WCH Art | W6: WCH Art | X6: WCH-R | Y6: WCH-S | Z6: WCH-C | AA6: Maas | AB6: Blind | AC6: Taub | AD6: Stre
A7: PC | B7: PC 5014 | C7: 01.12.2024 | D7: 00:20 | E7: 01.12.2024 | F7: 21:23 | G7: -21.05 | H7: Outbound | I7: 1 | J7: 0 | K7: 0 | L7: =I7+J7+K7 | M7: 0 | Q7: Ja | T7: AYT | U7: =VLOOKUP(T7,Destinations!$A$2:$C$550,2,0) | V7: WCHR | W7: =VLOOKUP(V7,'WCH Kat'!$A$1:$B$150,2,0)
A8: EW | B8: EW 5425 | C8: 01.12.2024 | D8: 00:40 | E8: 07.10.2024 | F8: 10:42 | G8: 1309.9667 | H8: Inbound | I8: 0 | J8: 0 | K8: 0 | L8: =I8+J8+K8 | M8: 1 | O8: Ja | T8: Las Palmas | U8: =VLOOKUP(T8,Destinations!$A$2:$C$550,2,0) | V8: WCHC | W8: =VLOOKUP(V8,'WCH Kat'!$A$1:$B$150,2,0)
A9: PC | B9: PC 1014 | C9: 01.12.2024 | D9: 00:55 | E9: 01.12.2024 | F9: 22:52 | G9: -21.95 | H9: Outbound | I9: 1 | J9: 0 | K9: 0 | L9: =I9+J9+K9 | M9: 0 | Q9: Ja | T9: Istanbul-Sabiha Gökcen | U9: =VLOOKUP(T9,Destinations!$A$2:$C$550,2,0) | V9: WCHS | W9: =VLOOKUP(V9,'WCH Kat'!$A$1:$B$150,2,0)
A10: NP | B10: NP 215 | C10: 01.12.2024 | D10: 08:11 | E10: 01.12.2024 | F10: 08:26 | G10: -0.25 | H10: Inbound | I10: 1 | J10: 0 | K10: 0 | L10: =I10+J10+K10 | M10: 0 | P10: Ja | T10: CAI | U10: =VLOOKUP(T10,Destinations!$A$2:$C$550,2,0) | V10: WCHC | W10: =VLOOKUP(V10,'WCH Kat'!$A$1:$B$150,2,0)
A11: NP | B11: NP 215 | C11: 01.12.2024 | D11: 08:11 | E11: 01.12.2024 | F11: 08:34 | G11: -0.38333 | H11: Inbound | I11: 1 | J11: 0 | K11: 0 | L11: =I11+J11+K11 | M11: 0 | R11: Ja | T11: CAI | U11: =VLOOKUP(T11,Destinations!$A$2:$C$550,2,0) | V11: WCHS | W11: =VLOOKUP(V11,'WCH Kat'!$A$1:$B$150,2,0)
A12: OS | B12: OS 195 | C12: 01.12.2024 | D12: 19:25 | E12: 01.12.2024 | F12: 19:45 | G12: -0.33333 | H12: Inbound | I12: 1 | J12: 0 | K12: 0 | L12: =I12+J12+K12 | M12: 0 | R12: Ja | T12: VIE | U12: =VLOOKUP(T12,Destinations!$A$2:$C$550,2,0) | V12: WCHR | W12: =VLOOKUP(V12,'WCH Kat'!$A$1:$B$150,2,0)
A13: BA | B13: BA 998 | C13: 02.12.2024 | D13: 18:25 | E13: 02.12.2024 | F13: 19:00 | G13: -0.58333 | H13: Inbound | I13: 1 | J13: 0 | K13: 0 | L13: =I13+J13+K13 | M13: 0 | P13: Ja | T13: LHR | U13: =VLOOKUP(T13,Destinations!$A$2:$C$550,2,0) | V13: WCHR | W13: =VLOOKUP(V13,'WCH Kat'!$A$1:$B$150,2,0)
A14: DI | B14: DI 6174 | C14: 04.12.2024 | D14: 09:40 | E14: 25.09.2024 | F14: 17:30 | G14: 1672.1667 | H14: Outbound | I14: 0 | J14: 0 | K14: 0 | L14: =I14+J14+K14 | M14: 1 | R14: Ja | T14: Hurghada | U14: =VLOOKUP(T14,Destinations!$A$2:$C$550,2,0) | V14: WCHS | W14: =VLOOKUP(V14,'WCH Kat'!$A$1:$B$150,2,0)
A15: PC | B15: PC 5014 | C15: 06.12.2024 | D15: 00:20 | E15: 06.12.2024 | F15: 22:37 | G15: -22.28333 | H15: Outbound | I15: 1 | J15: 0 | K15: 0 | L15: =I15+J15+K15 | M15: 0 | P15: Ja | T15: Antalya | U15: =VLOOKUP(T15,Destinations!$A$2:$C$550,2,0) | V15: WCHR | W15: =VLOOKUP(V15,'WCH Kat'!$A$1:$B$150,2,0)
A16: XC | B16: XC 1052 | C16: 06.12.2024 | D16: 13:20 | E16: 06.12.2024 | F16: 13:35 | G16: -0.25 | H16: Inbound | I16: 1 | J16: 0 | K16: 0 | L16: =I16+J16+K16 | M16: 0 | R16: Ja | T16: Antalya | U16: =VLOOKUP(T16,Destinations!$A$2:$C$550,2,0) | V16: WCHS | W16: =VLOOKUP(V16,'WCH Kat'!$A$1:$B$150,2,0)
A17: EW | B17: EW 817 | C17: 07.12.2024 | D17: 13:10 | E17: 07.12.2024 | F17: 21:25 | G17: -8.25 | H17: Inbound | I17: 1 | J17: 0 | K17: 0 | L17: =I17+J17+K17 | M17: 0 | R17: Ja | T17: CTA | U17: =VLOOKUP(T17,Destinations!$A$2:$C$550,2,0) | V17: WCHS | W17: =VLOOKUP(V17,'WCH Kat'!$A$1:$B$150,2,0)
A18: EW | B18: EW 817 | C18: 07.12.2024 | D18: 13:10 | E18: 07.12.2024 | F18: 21:25 | G18: -8.25 | H18: Inbound | I18: 1 | J18: 0 | K18: 0 | L18: =I18+J18+K18 | M18: 0 | R18: Ja | T18: CTA | U18: =VLOOKUP(T18,Destinations!$A$2:$C$550,2,0) | V18: WCHS | W18: =VLOOKUP(V18,'WCH Kat'!$A$1:$B$150,2,0)
A19: EW | B19: EW 817 | C19: 07.12.2024 | D19: 13:10 | E19: 07.12.2024 | F19: 21:25 | G19: -8.25 | H19: Inbound | I19: 1 | J19: 0 | K19: 0 | L19: =I19+J19+K19 | M19: 0 | R19: Ja | T19: CTA | U19: =VLOOKUP(T19,Destinations!$A$2:$C$550,2,0) | V19: WCHS | W19: =VLOOKUP(V19,'WCH Kat'!$A$1:$B$150,2,0)
A20: FR | B20: FR 1089 | C20: 08.12.2024 | D20: 00:20 | E20: 08.12.2024 | F20: 00:54 | G20: -0.56667 | H20: Inbound | I20: 1 | J20: 0 | K20: 0 | L20: =I20+J20+K20 | M20: 0 | R20: Ja | T20: Dublin | U20: =VLOOKUP(T20,Destinations!$A$2:$C$550,2,0) | V20: WCHS | W20: =VLOOKUP(V20,'WCH Kat'!$A$1:$B$150,2,0)
A21: FR | B21: FR ??? | C21: 08.12.2024 | D21: 00:20 | E21: 08.12.2024 | F21: 00:54 | G21: -0.56667 | H21: Inbound | I21: 1 | J21: 0 | K21: 0 | L21: =I21+J21+K21 | M21: 0 | R21: Ja | T21: Dublin | U21: =VLOOKUP(T21,Destinations!$A$2:$C$550,2,0) | V21: WCHS | W21: =VLOOKUP(V21,'WCH Kat'!$A$1:$B$150,2,0)
A22: FR | B22: FR ??? | C22: 08.12.2024 | D22: 00:20 | E22: 08.12.2024 | F22: 00:54 | G22: -0.56667 | H22: Inbound | I22: 1 | J22: 0 | K22: 0 | L22: =I22+J22+K22 | M22: 0 | R22: Ja | T22: Dublin | U22: =VLOOKUP(T22,Destinations!$A$2:$C$550,2,0) | V22: WCHS | W22: =VLOOKUP(V22,'WCH Kat'!$A$1:$B$150,2,0)
A23: FR | B23: FR ??? | C23: 08.12.2024 | D23: 00:20 | E23: 08.12.2024 | F23: 00:54 | G23: -0.56667 | H23: Inbound | I23: 1 | J23: 0 | K23: 0 | L23: =I23+J23+K23 | M23: 0 | R23: Ja | T23: Dublin | U23: =VLOOKUP(T23,Destinations!$A$2:$C$550,2,0) | V23: WCHS | W23: =VLOOKUP(V23,'WCH Kat'!$A$1:$B$150,2,0)
A24: FR | B24: FR ??? | C24: 08.12.2024 | D24: 01:00 | E24: 08.12.2024 | F24: 01:27 | G24: -0.45 | H24: Inbound | I24: 1 | J24: 0 | K24: 0 | L24: =I24+J24+K24 | M24: 0 | R24: Ja | T24: STN | U24: =VLOOKUP(T24,Destinations!$A$2:$C$550,2,0) | V24: WCHR | W24: =VLOOKUP(V24,'WCH Kat'!$A$1:$B$150,2,0)
A25: FR | B25: FR ??? | C25: 08.12.2024 | D25: 01:00 | E25: 08.12.2024 | F25: 01:27 | G25: -0.45 | H25: Inbound | I25: 1 | J25: 0 | K25: 0 | L25: =I25+J25+K25 | M25: 0 | R25: Ja | T25: STN | U25: =VLOOKUP(T25,Destinations!$A$2:$C$550,2,0) | V25: WCHR | W25: =VLOOKUP(V25,'WCH Kat'!$A$1:$B$150,2,0)
A26: FR | B26: FR ??? | C26: 08.12.2024 | D26: 01:00 | E26: 08.12.2024 | F26: 01:27 | G26: -0.45 | H26: Inbound | I26: 1 | J26: 0 | K26: 0 | L26: =I26+J26+K26 | M26: 0 | R26: Ja | T26: STN | U26: =VLOOKUP(T26,Destinations!$A$2:$C$550,2,0) | V26: WCHR | W26: =VLOOKUP(V26,'WCH Kat'!$A$1:$B$150,2,0)
A27: FR | B27: FR ??? | C27: 08.12.2024 | D27: 01:00 | E27: 08.12.2024 | F27: 01:27 | G27: -0.45 | H27: Inbound | I27: 1 | J27: 0 | K27: 0 | L27: =I27+J27+K27 | M27: 0 | R27: Ja | T27: STN | U27: =VLOOKUP(T27,Destinations!$A$2:$C$550,2,0) | V27: WCHR | W27: =VLOOKUP(V27,'WCH Kat'!$A$1:$B$150,2,0)
... A31: FR | B31: FR 2307 | C31: 10.12.2024 | D31: 19:05 | E31: 10.12.2024 | F31: 19:22 | G31: -0.28333 | H31: Inbound | I31: 1 | J31: 0 | K31: 0 | L31: =I31+J31+K31 | M31: 0 | R31: Ja | T31: Malaga | U31: =VLOOKUP(T31,Destinations!$A$2:$C$550,2,0) | V31: WCHC | W31: =VLOOKUP(V31,'WCH Kat'!$A$1:$B$150,2,0)
A32: FR | B32: FR 9840 | C32: 11.12.2024 | D32: 14:15 | E32: 26.11.2024 | F32: 16:48 | G32: 357.45 | H32: Outbound | I32: 0 | J32: 0 | K32: 0 | L32: =I32+J32+K32 | M32: 1 | O32: Ja | T32: Lissabon | U32: =VLOOKUP(T32,Destinations!$A$2:$C$550,2,0) | V32: WCHR | W32: =VLOOKUP(V32,'WCH Kat'!$A$1:$B$150,2,0)
A33: DI | B33: DI 6837 | C33: 12.12.2024 | D33: 18:25 | E33: 05.12.2024 | F33: 14:46 | G33: 171.65 | H33: Inbound | I33: 0 | J33: 0 | K33: 0 | L33: =I33+J33+K33 | M33: 1 | O33: Ja | T33: Teneriffa | U33: =VLOOKUP(T33,Destinations!$A$2:$C$550,2,0) | V33: WCHC | W33: =VLOOKUP(V33,'WCH Kat'!$A$1:$B$150,2,0)
A34: PC | B34: PC 5013 | C34: 13.12.2024 | D34: 21:40 | E34: 20.11.2024 | F34: 15:00 | G34: 558.66667 | H34: Inbound | I34: 0 | J34: 0 | K34: 0 | L34: =I34+J34+K34 | M34: 1 | R34: Ja | T34: Antalya | U34: =VLOOKUP(T34,Destinations!$A$2:$C$550,2,0) | V34: WCHS | W34: =VLOOKUP(V34,'WCH Kat'!$A$1:$B$150,2,0)
A35: FR | B35: FR 1355 | C35: 14.12.2024 | D35: 05:50 | E35: 06.12.2024 | F35: 10:55 | G35: 186.91667 | H35: Outbound | I35: 0 | J35: 0 | K35: 0 | L35: =I35+J35+K35 | M35: 1 | R35: Ja | T35: Alicante | U35: =VLOOKUP(T35,Destinations!$A$2:$C$550,2,0) | V35: WCHR | W35: =VLOOKUP(V35,'WCH Kat'!$A$1:$B$150,2,0)
A36: FR | B36: FR 303 | C36: 15.12.2024 | D36: 00:40 | E36: 15.12.2024 | F36: 00:59 | G36: -0.31667 | H36: Inbound | I36: 1 | J36: 0 | K36: 0 | L36: =I36+J36+K36 | M36: 0 | R36: Ja | T36: Las Palmas | U36: =VLOOKUP(T36,Destinations!$A$2:$C$550,2,0) | V36: WCHR | W36: =VLOOKUP(V36,'WCH Kat'!$A$1:$B$150,2,0)
A37: EW | B37: EW 789 | C37: 15.12.2024 | D37: 22:20 | E37: 20.11.2024 | F37: 18:41 | G37: 603.65 | H37: Inbound | I37: 0 | J37: 0 | K37: 0 | L37: =I37+J37+K37 | M37: 1 | O37: Ja | T37: Budapest | U37: =VLOOKUP(T37,Destinations!$A$2:$C$550,2,0) | V37: WCHS | W37: =VLOOKUP(V37,'WCH Kat'!$A$1:$B$150,2,0)
A38: TK | B38: TK 1675 | C38: 16.12.2024 | D38: 16:45 | E38: 02.12.2024 | F38: 13:45 | G38: 339 | H38: Inbound | I38: 0 | J38: 0 | K38: 0 | L38: =I38+J38+K38 | M38: 1 | N38: Ja | T38: IST | U38: =VLOOKUP(T38,Destinations!$A$2:$C$550,2,0) | V38: WCHR | W38: =VLOOKUP(V38,'WCH Kat'!$A$1:$B$150,2,0)
A39: PC | B39: PC 5014 | C39: 17.12.2024 | D39: 00:20 | E39: 17.12.2024 | F39: 22:45 | G39: -22.41667 | H39: Outbound | I39: 1 | J39: 0 | K39: 0 | L39: =I39+J39+K39 | M39: 0 | Q39: Ja | T39: AYT | U39: =VLOOKUP(T39,Destinations!$A$2:$C$550,2,0) | V39: WCHC | W39: =VLOOKUP(V39,'WCH Kat'!$A$1:$B$150,2,0)
A40: FR | B40: FR 2352 | C40: 18.12.2024 | E40: 18.12.2024 | F40: 08:45 | G40: -8.75 | H40: Inbound | I40: 1 | J40: 0 | K40: 0 | L40: =I40+J40+K40 | M40: 0 | R40: Ja | T40: London-Stansted | U40: =VLOOKUP(T40,Destinations!$A$2:$C$550,2,0) | V40: WCHR | W40: =VLOOKUP(V40,'WCH Kat'!$A$1:$B$150,2,0)
A41: LS1 | B41: LS1937 | C41: 18.12.2024 | D41: 17:06 | E41: 18.12.2024 | F41: 17:21 | G41: -0.25 | H41: Inbound | I41: 1 | J41: 0 | K41: 0 | L41: =I41+J41+K41 | M41: 0 | R41: Ja | T41: BHX | U41: =VLOOKUP(T41,Destinations!$A$2:$C$550,2,0) | V41: WCHS | W41: =VLOOKUP(V41,'WCH Kat'!$A$1:$B$150,2,0)
A42: PC | B42: PC 5014 | C42: 19.12.2024 | D42: 00:20 | E42: 19.12.2024 | F42: 21:57 | G42: -21.61667 | H42: Outbound | I42: 1 | J42: 0 | K42: 0 | L42: =I42+J42+K42 | M42: 0 | Q42: Ja | T42: Antalya | U42: =VLOOKUP(T42,Destinations!$A$2:$C$550,2,0) | V42: WCHS | W42: =VLOOKUP(V42,'WCH Kat'!$A$1:$B$150,2,0)
A43: XQ | B43: XQ 115 | C43: 19.12.2024 | D43: 00:45 | E43: 19.12.2024 | F43: 08:55 | G43: -8.16667 | H43: Outbound | I43: 1 | J43: 0 | K43: 0 | L43: =I43+J43+K43 | M43: 0 | N43: Ja | T43: AYT | U43: =VLOOKUP(T43,Destinations!$A$2:$C$550,2,0) | V43: WCHR | W43: =VLOOKUP(V43,'WCH Kat'!$A$1:$B$150,2,0)
A44: FR | B44: FR 1035 | C44: 19.12.2024 | D44: 06:00 | E44: 05.12.2024 | F44: 14:43 | G44: 327.28333 | H44: Outbound | I44: 0 | J44: 0 | K44: 0 | L44: =I44+J44+K44 | M44: 1 | O44: Ja | T44: Teneriffa | U44: =VLOOKUP(T44,Destinations!$A$2:$C$550,2,0) | V44: WCHR | W44: =VLOOKUP(V44,'WCH Kat'!$A$1:$B$150,2,0)
...

Sheet Destinations
A1: IATA | B1: Name
A2: ACE | B2: Arrecife
A3: ACH | B3: St. Gallen
A4: ADA | B4: Adana
A5: ADB | B5: Izmir
A6: AGA | B6: Agadir
A7: AGP | B7: Malaga
A8: AJR | B8: Arvidsjaur
A9: ALC | B9: Alicante
A10: AMS | B10: Amsterdam
A11: AOE | B11: Anadolu
A12: AOI | B12: Ancona
... A506: London | B506: London

Sheet WCH Kat
A1: IATA | B1: Name
A2: BLIND | B2: B
A3: BLND | B3: B
A4: DEAF | B4: S
A5: Dpax NoSho | B5: NO
A6: DPAXNOSHO | B6: NO
A7: DPNA | B7: M
A8: MAAS | B8: M
A9: MEDA | B9: C
A10: MEDAWCHS | B10: S
A11: MEQT | B11: C
A12: OP | B12: S
... A28: WCMP | B28: S

Sheet Einzelaufstellung_November_mast
C1: Gesamt | D1: Inb. | E1: % | F1: Out. | G1: % | H1: >36 | I1: % | J1: <36 | K1: % | L1: 3 - 36 | M1: % | N1: < 3 | O1: % | P1: < 1 | Q1: % | R1: Inb spät | T1: % | U1: Out spät | V1: % | X1: WCH-R | Y1: WCH-S | Z1: WCH-C | AA1: Maas | AB1: Blind | AC1: Taub | AD1: Stre
C2: =M4 | D2: =H4 | E2: =#N/A | F2: =H5 | G2: =#N/A | H2: =M5 | I2: =#N/A | J2: =L5 | K2: =#N/A | L2: =K5 | M2: =#N/A | N2: =J5 | O2: =#N/A | P2: =I5 | Q2: =#N/A | X2: =X5 | Y2: =Y5 | Z2: =Z5 | AA2: =AA5 | AB2: =AB5 | AC2: =AC5 | AD2: =AD5 | AE2: =M5
A4: INb | H4: =SUMPRODUCT(SUBTOTAL(3,INDIRECT("I"&ROW(H7:H10133)))*(H7:H10133="Inbound")) | M4: =L5+M5 | X4: =X5+Y5+Z5+AA5+AB5+AC5+AD5
A5: Out | H5: =SUMPRODUCT(SUBTOTAL(3,INDIRECT("I"&ROW(H7:H10133)))*(H7:H10133="Outbound")) | I5: =SUBTOTAL(9,I7:I10133) | J5: =SUBTOTAL(9,J7:J10133) | K5: =SUBTOTAL(9,K7:K10133) | L5: =SUBTOTAL(9,L7:L10133) | M5: =SUBTOTAL(9,M7:M10133) | X5: =SUMPRODUCT(SUBTOTAL(3,INDIRECT("W"&ROW(7:10133)))*($W$7:$W$10133="R")) | Y5: =SUMPRODUCT(SUBTOTAL(3,INDIRECT("W"&ROW(7:10133)))*($W$7:$W$10133="S")) | Z5: =SUMPRODUCT(SUBTOTAL(3,INDIRECT("W"&ROW(7:10133)))*($W$7:$W$10133="C")) | AA5: =SUMPRODUCT(SUBTOTAL(3,INDIRECT("W"&ROW(7:10133)))*($W$7:$W$10133="M")) | AB5: =SUMPRODUCT(SUBTOTAL(3,INDIRECT("W"&ROW(7:10133)))*($W$7:$W$10133="B")) | AC5: =SUMPRODUCT(SUBTOTAL(3,INDIRECT("W"&ROW(7:10133)))*($W$7:$W$10133="T")) | AD5: =SUMPRODUCT(SUBTOTAL(3,INDIRECT("W"&ROW(7:10133)))*($W$7:$W$10133="ST"))
A6: LVG | B6: FlugNr. | C6: E-Datum | D6: Zeit | E6: M. am | F6: M. um | G6: Stunden | H6: InOut | I6: < 1 h | J6: 1-3 h | K6: 3 - 36 h | L6: alle unter 36 | M6: > 36 h | N6: Sita | O6: E-Mail | P6: PSM | Q6: Staff | R6: Tel. | T6: von Airport | U6: von Airport | V6: WCH Art | W6: WCH Art | X6: WCH-R | Y6: WCH-S | Z6: WCH-C | AA6: Maas | AB6: Blind | AC6: Taub | AD6: Stre
A7: EW | B7: EW 383 | C7: 01.11.2023 | D7: 00:32 | E7: 16.08.2023 | F7: 14:54 | G7: 1833.6333 | H7: Inbound | I7: 0 | J7: 0 | K7: 0 | L7: =I7+J7+K7 | M7: 1 | O7: Ja | T7: Tunis | U7: =VLOOKUP(T7,Destinations!$A$2:$C$550,2,0) | V7: WCHS | W7: =VLOOKUP(V7,'WCH Kat'!$A$1:$B$150,2,0)
A8: EW | B8: EW 252 | C8: 01.11.2023 | D8: 12:30 | E8: 23.10.2023 | F8: 09:12 | G8: 219.3 | H8: Outbound | I8: 0 | J8: 0 | K8: 0 | L8: =I8+J8+K8 | M8: 1 | O8: Ja | T8: Teneriffa | U8: =VLOOKUP(T8,Destinations!$A$2:$C$550,2,0) | V8: WCHS | W8: =VLOOKUP(V8,'WCH Kat'!$A$1:$B$150,2,0)
A9: XQ | B9: XQ 115 | C9: 01.11.2023 | D9: 13:40 | E9: 19.10.2023 | F9: 15:31 | G9: 310.15 | H9: Outbound | I9: 0 | J9: 0 | K9: 0 | L9: =I9+J9+K9 | M9: 1 | R9: Ja | T9: Antalya | U9: =VLOOKUP(T9,Destinations!$A$2:$C$550,2,0) | V9: WCHS | W9: =VLOOKUP(V9,'WCH Kat'!$A$1:$B$150,2,0)
A10: XQ | B10: XQ 119 | C10: 02.11.2023 | D10: 00:30 | E10: 02.11.2023 | F10: 20:34 | G10: -20.06667 | H10: Outbound | I10: 1 | J10: 0 | K10: 0 | L10: =I10+J10+K10 | M10: 0 | Q10: Ja | T10: Antalya | U10: =VLOOKUP(T10,Destinations!$A$2:$C$550,2,0) | V10: WCHS | W10: =VLOOKUP(V10,'WCH Kat'!$A$1:$B$150,2,0)
A11: PC | B11: PC 5013 | C11: 02.11.2023 | D11: 01:57 | E11: 17.10.2023 | F11: 13:55 | G11: 372.03333 | H11: Inbound | I11: 0 | J11: 0 | K11: 0 | L11: =I11+J11+K11 | M11: 1 | R11: Ja | T11: Antalya | U11: =VLOOKUP(T11,Destinations!$A$2:$C$550,2,0) | V11: WCHS | W11: =VLOOKUP(V11,'WCH Kat'!$A$1:$B$150,2,0)
A12: PC | B12: PC 5013 | C12: 02.11.2023 | D12: 01:57 | E12: 01.01.2023 | F12: 21:20 | G12: 7300.6167 | H12: Inbound | I12: 0 | J12: 0 | K12: 0 | L12: =I12+J12+K12 | M12: 1 | P12: Ja | T12: Antalya | U12: =VLOOKUP(T12,Destinations!$A$2:$C$550,2,0) | V12: WCHS | W12: =VLOOKUP(V12,'WCH Kat'!$A$1:$B$150,2,0)
A13: PC | B13: PC 5013 | C13: 02.11.2023 | D13: 01:57 | E13: 01.01.2023 | F13: 21:20 | G13: 7300.6167 | H13: Inbound | I13: 0 | J13: 0 | K13: 0 | L13: =I13+J13+K13 | M13: 1 | P13: Ja | T13: Antalya | U13: =VLOOKUP(T13,Destinations!$A$2:$C$550,2,0) | V13: WCHS | W13: =VLOOKUP(V13,'WCH Kat'!$A$1:$B$150,2,0)
A14: PC | B14: PC 5013 | C14: 02.11.2023 | D14: 01:57 | E14: 01.01.2023 | F14: 21:20 | G14: 7300.6167 | H14: Inbound | I14: 0 | J14: 0 | K14: 0 | L14: =I14+J14+K14 | M14: 1 | P14: Ja | T14: Antalya | U14: =VLOOKUP(T14,Destinations!$A$2:$C$550,2,0) | V14: WCHS | W14: =VLOOKUP(V14,'WCH Kat'!$A$1:$B$150,2,0)
A15: XQ | B15: XQ 988 | C15: 02.11.2023 | D15: 06:00 | E15: 02.11.2023 | F15: 10:32 | G15: -4.53333 | H15: Inbound | I15: 1 | J15: 0 | K15: 0 | L15: =I15+J15+K15 | M15: 0 | R15: Ja | T15: ADB | U15: =VLOOKUP(T15,Destinations!$A$2:$C$550,2,0) | V15: WCHS | W15: =VLOOKUP(V15,'WCH Kat'!$A$1:$B$150,2,0)
A16: XQ | B16: XQ 988 | C16: 02.11.2023 | D16: 06:00 | E16: 02.11.2023 | F16: 10:32 | G16: -4.53333 | H16: Inbound | I16: 1 | J16: 0 | K16: 0 | L16: =I16+J16+K16 | M16: 0 | R16: Ja | T16: ADB | U16: =VLOOKUP(T16,Destinations!$A$2:$C$550,2,0) | V16: WCHS | W16: =VLOOKUP(V16,'WCH Kat'!$A$1:$B$150,2,0)
A17: XQ | B17: XQ 988 | C17: 02.11.2023 | D17: 06:00 | E17: 02.11.2023 | F17: 10:32 | G17: -4.53333 | H17: Inbound | I17: 1 | J17: 0 | K17: 0 | L17: =I17+J17+K17 | M17: 0 | R17: Ja | T17: ADB | U17: =VLOOKUP(T17,Destinations!$A$2:$C$550,2,0) | V17: WCHS | W17: =VLOOKUP(V17,'WCH Kat'!$A$1:$B$150,2,0)
A18: XQ | B18: XQ 988 | C18: 02.11.2023 | D18: 06:00 | E18: 02.11.2023 | F18: 10:32 | G18: -4.53333 | H18: Inbound | I18: 1 | J18: 0 | K18: 0 | L18: =I18+J18+K18 | M18: 0 | R18: Ja | T18: ADB | U18: =VLOOKUP(T18,Destinations!$A$2:$C$550,2,0) | V18: WCHS | W18: =VLOOKUP(V18,'WCH Kat'!$A$1:$B$150,2,0)
A19: XQ | B19: XQ 988 | C19: 02.11.2023 | D19: 06:00 | E19: 02.11.2023 | F19: 10:32 | G19: -4.53333 | H19: Inbound | I19: 1 | J19: 0 | K19: 0 | L19: =I19+J19+K19 | M19: 0 | R19: Ja | T19: ADB | U19: =VLOOKUP(T19,Destinations!$A$2:$C$550,2,0) | V19: WCHS | W19: =VLOOKUP(V19,'WCH Kat'!$A$1:$B$150,2,0)
A20: XQ | B20: XQ 988 | C20: 02.11.2023 | D20: 06:00 | E20: 02.11.2023 | F20: 10:32 | G20: -4.53333 | H20: Inbound | I20: 1 | J20: 0 | K20: 0 | L20: =I20+J20+K20 | M20: 0 | R20: Ja | T20: ADB | U20: =VLOOKUP(T20,Destinations!$A$2:$C$550,2,0) | V20: WCHS | W20: =VLOOKUP(V20,'WCH Kat'!$A$1:$B$150,2,0)
A21: XQ | B21: XQ 988 | C21: 02.11.2023 | D21: 06:00 | E21: 02.11.2023 | F21: 10:32 | G21: -4.53333 | H21: Inbound | I21: 1 | J21: 0 | K21: 0 | L21: =I21+J21+K21 | M21: 0 | R21: Ja | T21: ADB | U21: =VLOOKUP(T21,Destinations!$A$2:$C$550,2,0) | V21: WCHS | W21: =VLOOKUP(V21,'WCH Kat'!$A$1:$B$150,2,0)
A22: PC | B22: PC 1661 | C22: 02.11.2023 | D22: 06:30 | E22: 02.11.2023 | F22: 07:50 | G22: -1.33333 | H22: Inbound | I22: 1 | J22: 0 | K22: 0 | L22: =I22+J22+K22 | M22: 0 | R22: Ja | T22: tzx | U22: =VLOOKUP(T22,Destinations!$A$2:$C$550,2,0) | V22: UNK | W22: =VLOOKUP(V22,'WCH Kat'!$A$1:$B$150,2,0)
A23: PC | B23: PC 1661 | C23: 02.11.2023 | D23: 06:30 | E23: 02.11.2023 | F23: 07:50 | G23: -1.33333 | H23: Inbound | I23: 1 | J23: 0 | K23: 0 | L23: =I23+J23+K23 | M23: 0 | R23: Ja | T23: tzx | U23: =VLOOKUP(T23,Destinations!$A$2:$C$550,2,0) | V23: UNK | W23: =VLOOKUP(V23,'WCH Kat'!$A$1:$B$150,2,0)
A24: PC | B24: PC 1661 | C24: 02.11.2023 | D24: 06:30 | E24: 02.11.2023 | F24: 07:50 | G24: -1.33333 | H24: Inbound | I24: 1 | J24: 0 | K24: 0 | L24: =I24+J24+K24 | M24: 0 | R24: Ja | T24: tzx | U24: =VLOOKUP(T24,Destinations!$A$2:$C$550,2,0) | V24: UNK | W24: =VLOOKUP(V24,'WCH Kat'!$A$1:$B$150,2,0)
A25: PC | B25: PC 1661 | C25: 02.11.2023 | D25: 06:30 | E25: 02.11.2023 | F25: 07:50 | G25: -1.33333 | H25: Inbound | I25: 1 | J25: 0 | K25: 0 | L25: =I25+J25+K25 | M25: 0 | R25: Ja | T25: tzx | U25: =VLOOKUP(T25,Destinations!$A$2:$C$550,2,0) | V25: UNK | W25: =VLOOKUP(V25,'WCH Kat'!$A$1:$B$150,2,0)
A26: PC | B26: PC 1661 | C26: 02.11.2023 | D26: 06:30 | E26: 02.11.2023 | F26: 07:50 | G26: -1.33333 | H26: Inbound | I26: 1 | J26: 0 | K26: 0 | L26: =I26+J26+K26 | M26: 0 | R26: Ja | T26: tzx | U26: =VLOOKUP(T26,Destinations!$A$2:$C$550,2,0) | V26: UNK | W26: =VLOOKUP(V26,'WCH Kat'!$A$1:$B$150,2,0)
... A74: W6 | B74: W6 4091 | C74: 02.11.2023 | D74: 15:30 | E74: 02.11.2023 | F74: 16:10 | G74: -0.66667 | H74: Inbound | I74: 1 | J74: 0 | K74: 0 | L74: =I74+J74+K74 | M74: 0 | R74: Ja | T74: BEG | U74: =VLOOKUP(T74,Destinations!$A$2:$C$550,2,0) | V74: WCHS | W74: =VLOOKUP(V74,'WCH Kat'!$A$1:$B$150,2,0)
A75: FR | B75: FR 9323 | C75: 02.11.2023 | D75: 23:15 | E75: 02.11.2023 | F75: 23:24 | G75: -0.15 | H75: Inbound | I75: 1 | J75: 0 | K75: 0 | L75: =I75+J75+K75 | M75: 0 | P75: Ja | T75: Aqaba | U75: =VLOOKUP(T75,Destinations!$A$2:$C$550,2,0) | V75: WCHR | W75: =VLOOKUP(V75,'WCH Kat'!$A$1:$B$150,2,0)
A76: XQ | B76: XQ 119 | C76: 03.11.2023 | D76: 00:30 | E76: 03.11.2023 | F76: 21:16 | G76: -20.76667 | H76: Outbound | I76: 1 | J76: 0 | K76: 0 | L76: =I76+J76+K76 | M76: 0 | Q76: Ja | T76: AYT | U76: =VLOOKUP(T76,Destinations!$A$2:$C$550,2,0) | V76: WCHS | W76: =VLOOKUP(V76,'WCH Kat'!$A$1:$B$150,2,0)
A77: W4 | B77: W4 3867 | C77: 04.11.2023 | D77: 00:05 | E77: 04.11.2023 | F77: 21:40 | G77: -21.58333 | H77: Inbound | I77: 1 | J77: 0 | K77: 0 | L77: =I77+J77+K77 | M77: 0 | P77: Ja | T77: Tirana | U77: =VLOOKUP(T77,Destinations!$A$2:$C$550,2,0) | V77: WCHS | W77: =VLOOKUP(V77,'WCH Kat'!$A$1:$B$150,2,0)
A78: 3O | B78: 3O 223 | C78: 04.11.2023 | D78: 10:55 | E78: 04.11.2023 | F78: 11:15 | G78: -0.33333 | H78: Inbound | I78: 1 | J78: 0 | K78: 0 | L78: =I78+J78+K78 | M78: 0 | R78: Ja | T78: NDR | U78: =VLOOKUP(T78,Destinations!$A$2:$C$550,2,0) | V78: WCHS | W78: =VLOOKUP(V78,'WCH Kat'!$A$1:$B$150,2,0)
A79: 3O | B79: 3O 223 | C79: 04.11.2023 | D79: 10:55 | E79: 04.11.2023 | F79: 11:15 | G79: -0.33333 | H79: Inbound | I79: 1 | J79: 0 | K79: 0 | L79: =I79+J79+K79 | M79: 0 | R79: Ja | T79: NDR | U79: =VLOOKUP(T79,Destinations!$A$2:$C$550,2,0) | V79: WCHS | W79: =VLOOKUP(V79,'WCH Kat'!$A$1:$B$150,2,0)
A80: XQ | B80: XQ 1336 | C80: 04.11.2023 | D80: 18:08 | E80: 04.11.2023 | F80: 18:23 | G80: -0.25 | H80: Inbound | I80: 1 | J80: 0 | K80: 0 | L80: =I80+J80+K80 | M80: 0 | R80: Ja | T80: Zonguldak | U80: =VLOOKUP(T80,Destinations!$A$2:$C$550,2,0) | V80: WCHS | W80: =VLOOKUP(V80,'WCH Kat'!$A$1:$B$150,2,0)
A81: XQ | B81: XQ 1336 | C81: 04.11.2023 | D81: 18:08 | E81: 04.11.2023 | F81: 18:23 | G81: -0.25 | H81: Inbound | I81: 1 | J81: 0 | K81: 0 | L81: =I81+J81+K81 | M81: 0 | R81: Ja | T81: Zonguldak | U81: =VLOOKUP(T81,Destinations!$A$2:$C$550,2,0) | V81: WCHS | W81: =VLOOKUP(V81,'WCH Kat'!$A$1:$B$150,2,0)
A82: XQ | B82: XQ 1336 | C82: 04.11.2023 | D82: 18:08 | E82: 04.11.2023 | F82: 18:23 | G82: -0.25 | H82: Inbound | I82: 1 | J82: 0 | K82: 0 | L82: =I82+J82+K82 | M82: 0 | R82: Ja | T82: Zonguldak | U82: =VLOOKUP(T82,Destinations!$A$2:$C$550,2,0) | V82: WCHS | W82: =VLOOKUP(V82,'WCH Kat'!$A$1:$B$150,2,0)
A83: XQ | B83: XQ 1336 | C83: 04.11.2023 | D83: 18:08 | E83: 04.11.2023 | F83: 18:23 | G83: -0.25 | H83: Inbound | I83: 1 | J83: 0 | K83: 0 | L83: =I83+J83+K83 | M83: 0 | R83: Ja | T83: Zonguldak | U83: =VLOOKUP(T83,Destinations!$A$2:$C$550,2,0) | V83: WCHS | W83: =VLOOKUP(V83,'WCH Kat'!$A$1:$B$150,2,0)
A84: XQ | B84: XQ 1336 | C84: 04.11.2023 | D84: 18:08 | E84: 04.11.2023 | F84: 18:23 | G84: -0.25 | H84: Inbound | I84: 1 | J84: 0 | K84: 0 | L84: =I84+J84+K84 | M84: 0 | R84: Ja | T84: Zonguldak | U84: =VLOOKUP(T84,Destinations!$A$2:$C$550,2,0) | V84: WCHS | W84: =VLOOKUP(V84,'WCH Kat'!$A$1:$B$150,2,0)
A85: XQ | B85: XQ 1336 | C85: 04.11.2023 | D85: 18:08 | E85: 04.11.2023 | F85: 18:23 | G85: -0.25 | H85: Inbound | I85: 1 | J85: 0 | K85: 0 | L85: =I85+J85+K85 | M85: 0 | R85: Ja | T85: Zonguldak | U85: =VLOOKUP(T85,Destinations!$A$2:$C$550,2,0) | V85: WCHS | W85: =VLOOKUP(V85,'WCH Kat'!$A$1:$B$150,2,0)
A86: XQ | B86: XQ 1336 | C86: 04.11.2023 | D86: 18:08 | E86: 04.11.2023 | F86: 18:23 | G86: -0.25 | H86: Inbound | I86: 1 | J86: 0 | K86: 0 | L86: =I86+J86+K86 | M86: 0 | R86: Ja | T86: Zonguldak | U86: =VLOOKUP(T86,Destinations!$A$2:$C$550,2,0) | V86: WCHS | W86: =VLOOKUP(V86,'WCH Kat'!$A$1:$B$150,2,0)
A87: XQ | B87: XQ 1336 | C87: 04.11.2023 | D87: 18:08 | E87: 04.11.2023 | F87: 18:23 | G87: -0.25 | H87: Inbound | I87: 1 | J87: 0 | K87: 0 | L87: =I87+J87+K87 | M87: 0 | R87: Ja | T87: Zonguldak | U87: =VLOOKUP(T87,Destinations!$A$2:$C$550,2,0) | V87: WCHS | W87: =VLOOKUP(V87,'WCH Kat'!$A$1:$B$150,2,0)
A88: XQ | B88: XQ 1336 | C88: 04.11.2023 | D88: 18:08 | E88: 04.11.2023 | F88: 18:23 | G88: -0.25 | H88: Inbound | I88: 1 | J88: 0 | K88: 0 | L88: =I88+J88+K88 | M88: 0 | R88: Ja | T88: Zonguldak | U88: =VLOOKUP(T88,Destinations!$A$2:$C$550,2,0) | V88: WCHS | W88: =VLOOKUP(V88,'WCH Kat'!$A$1:$B$150,2,0)
...
